Workbook

Sheet 1-GASTOS MERCADO 2025
A1: FECHA | B1: MONTO | C1: DESCRIPCION | D1: MES | E1: LUGAR
A2: 45659 | B2: 49940 | C2: COMPRA CARNES | D2: ENERO | E2: FLORENCIA | H2: MES | I2: MONTO | J2: VARIACIÓN PORCENTUAL | K2: ESTADO DE LA VARIACIÓN
A3: 45661 | B3: 206950 | C3: COMPRA DROGAS | D3: ENERO | E3: FLORENCIA | H3: MES ENERO | I3: =SUM(B2:B10) -> 1323709
A4: 45661 | B4: 34631 | C4: COMPRA MERCADO | D4: ENERO | E4: FLORENCIA | H4: MES FEBRERO | I4: =SUM(B11:B23) -> 1174701 | J4: =(I4-I3)/I3 -> -0.11256855 | K4: =IF(J4<0,"BAJÓ EL GASTO",IF(J4=0,"GASTO ESTABLE","SUBIÓ EL GASTO")) -> BAJÓ EL GASTO
A5: 45661 | B5: 81883 | C5: COMPRA DROGAS | D5: ENERO | E5: FLORENCIA | H5: MES MARZO | I5: =SUM(B28:B46) -> 1439280 | J5: =(I5-I4)/I4 -> 0.22523093 | K5: =IF(J5<0,"BAJÓ EL GASTO",IF(J5=0,"GASTO ESTABLE","SUBIÓ EL GASTO")) -> SUBIÓ EL GASTO
A6: 45661 | B6: 56000 | C6: GAFAS | D6: ENERO | E6: FLORENCIA | H6: MES ABRIL | I6: =SUM(B47:B66) -> 1072159 | J6: =(I6-I5)/I5 -> -0.25507268 | K6: =IF(J6<0,"BAJÓ EL GASTO",IF(J6=0,"GASTO ESTABLE","SUBIÓ EL GASTO")) -> BAJÓ EL GASTO
A7: 45683 | B7: 12323 | C7: COMPRA MERCADO | D7: ENERO | E7: FLORENCIA | H7: MES MAYO | I7: =SUM(B67:B86) -> 1448121 | J7: =(I7-I6)/I6 -> 0.35065881 | K7: =IF(J7<0,"BAJÓ EL GASTO",IF(J7=0,"GASTO ESTABLE","SUBIÓ EL GASTO")) -> SUBIÓ EL GASTO
A8: 45683 | B8: 19700 | C8: COMPRA MERCADO | D8: ENERO | E8: FLORENCIA | H8: MES JUNIO | I8: =SUM(B87:B105) -> 1492803 | J8: =(I8-I7)/I7 -> 0.030855156 | K8: =IF(J8<0,"BAJÓ EL GASTO",IF(J8=0,"GASTO ESTABLE","SUBIÓ EL GASTO")) -> SUBIÓ EL GASTO
A9: 45684 | B9: 169630 | C9: COMPRA MERCADO | D9: ENERO | E9: FLORENCIA | H9: MES JULIO | I9: =SUM(B106:B120) -> 1678099 | J9: =(I9-I8)/I8 -> 0.12412622 | K9: =IF(J9<0,"BAJÓ EL GASTO",IF(J9=0,"GASTO ESTABLE","SUBIÓ EL GASTO")) -> SUBIÓ EL GASTO
A10: 45685 | B10: 692652 | C10: COMPRA MERCADO | D10: ENERO | E10: FLORENCIA | H10: MES AGOSTO | I10: =SUM(B121:B144) -> 2203667 | J10: =(I10-I9)/I9 -> 0.31319249 | K10: =IF(J10<0,"BAJÓ EL GASTO",IF(J10=0,"GASTO ESTABLE","SUBIÓ EL GASTO")) -> SUBIÓ EL GASTO
A11: 45689 | B11: 72400 | C11: COMPRA DE VITAMINAS | D11: FEBRERO | E11: FLORENCIA | H11: MES SEPTIEMBRE | I11: =SUM(B145:B172) -> 1973222 | J11: =(I11-I10)/I10 -> -0.10457342 | K11: =IF(J11<0,"BAJÓ EL GASTO",IF(J11=0,"GASTO ESTABLE","SUBIÓ EL GASTO")) -> BAJÓ EL GASTO
A12: 45693 | B12: 23800 | C12: COMPRA CHORIZOS | D12: FEBRERO | E12: FLORENCIA | H12: MES OCTUBRE | I12: =SUM(B173:B219) -> 3202187 | J12: =(I12-I11)/I11 -> 0.62282146 | K12: =IF(J12<0,"BAJÓ EL GASTO",IF(J12=0,"GASTO ESTABLE","SUBIÓ EL GASTO")) -> SUBIÓ EL GASTO
A13: 45697 | B13: 50000 | C13: COMPRA DE CARNES | D13: FEBRERO | E13: FLORENCIA | H13: MES NOVIEMBRE | I13: =SUM(B220:B267) -> 2489416 | J13: =(I13-I12)/I12 -> -0.22258881 | K13: =IF(J13<0,"BAJÓ EL GASTO",IF(J13=0,"GASTO ESTABLE","SUBIÓ EL GASTO")) -> BAJÓ EL GASTO
A14: 45698 | B14: 282500 | C14: COMPRA DE MERCADO | D14: FEBRERO | E14: FLORENCIA | H14: MES DICIEMBRE | I14: =SUM(B268:B332) -> 2271421 | J14: =(I14-I13)/I13 -> -0.087568731 | K14: =IF(J14<0,"BAJÓ EL GASTO",IF(J14=0,"GASTO ESTABLE","SUBIÓ EL GASTO")) -> BAJÓ EL GASTO
A15: 45699 | B15: 17829 | C15: COMPRA DE MERCADO | D15: FEBRERO | E15: FLORENCIA
A16: 45699 | B16: 8000 | C16: COMPRA BOLSA DE BASURA | D16: FEBRERO | E16: FLORENCIA
A17: 45705 | B17: 65555 | C17: COMPRA MERCADO | D17: FEBRERO | E17: FLORENCIA
A18: 45707 | B18: 171400 | C18: COMPRA MEDICINA | D18: FEBRERO | E18: FLORENCIA
A19: 45707 | B19: 11555 | C19: COMPRA MERCADO | D19: FEBRERO | E19: FLORENCIA
A20: 45710 | B20: 69963 | C20: COMPRA MERCADO | D20: FEBRERO | E20: FLORENCIA
A21: 45344 | B21: 91303 | C21: COMPRA MERCADO | D21: FEBRERO | E21: FLORENCIA
A22: 45346 | B22: 29596 | C22: COMPRA DE CARNES | D22: FEBRERO | E22: FLORENCIA
A23: 45713 | B23: 280800 | C23: COMPRA MERCADO | D23: FEBRERO | E23: FLORENCIA
A24: 45349 | B24: 113650 | C24: COMPRA MERCADO | D24: FEBRERO | E24: FLORENCIA
A25: 45349 | B25: 62040 | C25: COMPRA MERCADO | D25: FEBRERO | E25: FLORENCIA
A26: 45349 | B26: 35000 | C26: COMPRA MERCADO | D26: FEBRERO | E26: FLORENCIA
... A100: 45833 | B100: 13500 | C100: COMPRA PAPELES | D100: JUNIO | E100: FLORENCIA
A101: 25/26/2025 | B101: 325746 | C101: COMPRA DE MERCADO | D101: JUNIO | E101: FLORENCIA
A102: 45834 | B102: 20700 | C102: COMPRA DE MERCADO | D102: JUNIO | E102: FLORENCIA
A103: 45835 | B103: 27034 | C103: COMPRA DE MERCADO | D103: JUNIO | E103: FLORENCIA
A104: 45838 | B104: 148521 | C104: COMPRA DE MERCADO | D104: JUNIO | E104: FLORENCIA
A105: 45838 | B105: 250000 | C105: COMPRA DE MERCADO | D105: JUNIO | E105: FLORENCIA
A106: 45841 | B106: 35400 | C106: COMPRA DE MERCADO | D106: JULIO | E106: FLORENCIA
A107: 45843 | B107: 218908 | C107: COMPRA DE MERCADO | D107: JULIO | E107: FLORENCIA
A108: 45845 | B108: 35400 | C108: COMPRA DE MERCADO | D108: JULIO | E108: FLORENCIA
A109: 45849 | B109: 43244 | C109: COMPRA DE MERCADO | D109: JULIO | E109: FLORENCIA
A110: 45850 | B110: 426815 | C110: COMPRA DE MERCADO | D110: JULIO | E110: FLORENCIA
A111: 45852 | B111: 140500 | C111: TANQUEO CARRO | D111: JULIO | E111: FLORENCIA
A112: 45854 | B112: 45300 | C112: COMPRA DE MERCADO | D112: JULIO | E112: FLORENCIA
A113: 45860 | B113: 268092 | C113: COMPRA DE MERCADO | D113: JULIO | E113: FLORENCIA
...

Sheet 2-GASTOS OCIO U OTROS
A1: FECHA | B1: MONTO | C1: DESCRIPCION | D1: MES | E1: LUGAR | F1: ESTABLECIMIENTO | G1: CONTEXTO
A2: 45686 | B2: 11000200 | C2: EJECUCIÓN PLAN VACACIONAL | D2: ENERO | E2: FLORENCIA | F2: CENTRO | G2: PLAN VACACIONAL | J2: MES | K2: MONTO | L2: VARIACIÓN PORCENTUAL | M2: ESTADO DE LA VARIACIÓN
A3: 45694 | B3: 40000 | C3: COMPRA PICADAS CHICHARRON | D3: FEBRERO | E3: FLORENCIA | F3: CENTRO | G3: CENA | J3: MES ENERO | K3: =B2 -> 11000200
A4: 45698 | B4: 84000 | C4: CENA DONDE FUENTE | D4: FEBRERO | E4: FLORENCIA | F4: FUENTE | G4: CENA | J4: MES FEBRERO | K4: =SUM(B4:B5) -> 134000 | L4: =(K4-K3)/K3 -> -0.9878184 | M4: =IF(L4<0,"BAJÓ EL GASTO",IF(L4=0,"GASTO ESTABLE","SUBIÓ EL GASTO")) -> BAJÓ EL GASTO
A5: 45710 | B5: 50000 | C5: CENA DONDE FUENTE | D5: FEBRERO | E5: FLORENCIA | F5: FUENTE | G5: CENA | J5: MES MARZO | K5: =SUM(B6:B7) -> 220000 | L5: =(K5-K4)/K4 -> 0.64179104 | M5: =IF(L5<0,"BAJÓ EL GASTO",IF(L5=0,"GASTO ESTABLE","SUBIÓ EL GASTO")) -> SUBIÓ EL GASTO
A6: 45725 | B6: 120000 | C6: ALMUERZO PESCADO DONDE EL PAISA | D6: MARZO | E6: FLORENCIA | F6: PAISA | G6: CENA | J6: MES ABRIL | K6: =SUM(B8:B11) -> 957000 | L6: =(K6-K5)/K5 -> 3.35 | M6: =IF(L6<0,"BAJÓ EL GASTO",IF(L6=0,"GASTO ESTABLE","SUBIÓ EL GASTO")) -> SUBIÓ EL GASTO
A7: 45739 | B7: 100000 | C7: ALMUERZO FIN DE SEMANA DANILO | D7: MARZO | E7: FLORENCIA | F7: PAISA | G7: CENA | J7: MES MAYO | K7: =SUM(B12:B21) -> 500500 | L7: =(K7-K6)/K6 -> -0.47701149 | M7: =IF(L7<0,"BAJÓ EL GASTO",IF(L7=0,"GASTO ESTABLE","SUBIÓ EL GASTO")) -> BAJÓ EL GASTO
A8: 45750 | B8: 107000 | C8: CENA DONDE FUENTE | D8: ABRIL | E8: FLORENCIA | F8: FUENTE | G8: CENA | J8: MES JUNIO | K8: =SUM(B22:B27) -> 204000 | L8: =(K8-K7)/K7 -> -0.59240759 | M8: =IF(L8<0,"BAJÓ EL GASTO",IF(L8=0,"GASTO ESTABLE","SUBIÓ EL GASTO")) -> BAJÓ EL GASTO
A9: 45753 | B9: 130000 | C9: PASEO A EL DONCELLO | D9: ABRIL | E9: FLORENCIA | F9: _____ | G9: _____ | J9: MES JULIO | K9: =SUM(B28:B31) -> 147000 | L9: =(K9-K8)/K8 -> -0.27941176 | M9: =IF(L9<0,"BAJÓ EL GASTO",IF(L9=0,"GASTO ESTABLE","SUBIÓ EL GASTO")) -> BAJÓ EL GASTO
A10: 45755 | B10: 520000 | C10: FIESTA CUMPLAÑOS CINDY | D10: ABRIL | E10: FLORENCIA | F10: DOS BOCADOS | G10: CENA | J10: MES AGOSTO | K10: =SUM(B32:B39) -> 565000 | L10: =(K10-K9)/K9 -> 2.8435374 | M10: =IF(L10<0,"BAJÓ EL GASTO",IF(L10=0,"GASTO ESTABLE","SUBIÓ EL GASTO")) -> SUBIÓ EL GASTO
A11: 45757 | B11: 200000 | C11: COMPRA COMIDA SEMANA SANTA | D11: ABRIL | E11: FLORENCIA | F11: _____ | G11: _____ | J11: MES SEPTIEMBRE | K11: =SUM(B40:B50) -> 348000 | L11: =(K11-K10)/K10 -> -0.3840708 | M11: =IF(L11<0,"BAJÓ EL GASTO",IF(L11=0,"GASTO ESTABLE","SUBIÓ EL GASTO")) -> BAJÓ EL GASTO
A12: 45780 | B12: 150000 | C12: PAGO PASEO SANCOCHO DIRA DANILO | D12: ABRIL | E12: FLORENCIA | F12: _____ | G12: _____ | J12: MES OCTUBRE | K12: =SUM(B54:B57) -> 172000 | L12: =(K12-K11)/K11 -> -0.50574713 | M12: =IF(L12<0,"BAJÓ EL GASTO",IF(L12=0,"GASTO ESTABLE","SUBIÓ EL GASTO")) -> BAJÓ EL GASTO
A13: 45789 | B13: 40000 | C13: COMPRA TORTA DELICAPRICCIO | D13: MAYO | E13: FLORENCIA | F13: _____ | G13: _____ | J13: MES NOVIEMBRE | K13: =SUM(B58:B65) -> 322000 | L13: =(K13-K12)/K12 -> 0.87209302 | M13: =IF(L13<0,"BAJÓ EL GASTO",IF(L13=0,"GASTO ESTABLE","SUBIÓ EL GASTO")) -> SUBIÓ EL GASTO
A14: 45789 | B14: 44000 | C14: COMPRA PIZZETAS LABOYANA | D14: MAYO | E14: FLORENCIA | F14: _____ | G14: _____ | J14: MES DICIEMBRE | K14: =SUM(B66:B114) -> 838900 | L14: =(K14-K13)/K13 -> 1.6052795 | M14: =IF(L14<0,"BAJÓ EL GASTO",IF(L14=0,"GASTO ESTABLE","SUBIÓ EL GASTO")) -> SUBIÓ EL GASTO
A15: 45791 | B15: 40000 | C15: COMPRA DE CHICHARRONES | D15: MAYO | E15: FLORENCIA | F15: _____ | G15: _____
A16: 45795 | B16: 25000 | C16: COMPRA ALMUERZO LLANERO | D16: MAYO | E16: FLORENCIA | F16: ASADOS CAQUETEÑOS | G16: ALMUERZO
A17: 45797 | B17: 51500 | C17: HAMBUERGUESAS | D17: MAYO | E17: FLORENCIA | F17: YUYIS | G17: CENA | J17: TOTAL GASTOS CASA EN OCIO
A18: 45801 | B18: 50000 | C18: HAMBUERGUESAS | D18: MAYO | E18: FLORENCIA | F18: LA CIUDADELA | G18: CENA | J18: =SUM(B2:B140) -> 15670600
A19: 45804 | B19: 35000 | C19: PAGO COMIDA | D19: MAYO | E19: FLORENCIA | F19: CENTRO | G19: ALMUERZO
A20: 45804 | B20: 13000 | C20: TAMALES | D20: MAYO | E20: FLORENCIA | F20: CENTRO | G20: CENA
A21: 45804 | B21: 52000 | C21: COMPRA PICADAS CHICHARRON | D21: MAYO | E21: FLORENCIA | F21: CENTRO | G21: CENA
A22: 45814 | B22: 40000 | C22: COMPRA DE PIZZAS | D22: JUNIO | E22: FLORENCIA | F22: CASA | G22: CENA
A23: 09/-06/2025 | B23: 26000 | C23: ALMUERZO | D23: JUNIO | E23: FLORENCIA | F23: CASA | G23: ALMUERZO
A24: 45823 | B24: 20000 | C24: PAGO DESAYUNO | D24: JUNIO | E24: FLORENCIA | F24: CANELOS | G24: DESAYUNO
A25: 45823 | B25: 72000 | C25: COMPRA DE ALMUERZOS | D25: JUNIO | E25: MORELIA | F25: NAYAWID | G25: ALMUERZO
A26: 45823 | B26: 20000 | C26: COMPRA ARROZ CON LECHE | D26: JUNIO | E26: FLORENCIA | G26: MERIENDA
A27: 45833 | B27: 26000 | C27: ALMUERZO | D27: JUNIO | E27: FLORENCIA | F27: CASA | G27: ALMUERZO
A28: 45850 | B28: 25000 | C28: LAS GARZAS | D28: JULIO | E28: FLORENCIA | F28: CASA | G28: DESAYUNO
A29: 45852 | B29: 47000 | C29: COMPRA CHICHARRONES | D29: JULIO | E29: FLORENCIA | F29: CENTRO | G29: CENA
A30: 45861 | B30: 25000 | C30: COMPRA DE POLLO | D30: JULIO | E30: FLORENCIA | F30: CENTRO | G30: CENA
A31: 45863 | B31: 50000 | C31: HAMBURGUESA | D31: JULIO | E31: FLORENCIA | F31: CENTRO | G31: CENA
A32: 45878 | B32: 30000 | C32: ALMNUERZO | D32: AGOSTO | E32: FLORENCIA | F32: LAS GARZAS | G32: ALMUERZO
A33: 45879 | B33: 100000 | C33: ALMNUERZO | D33: AGOSTO | E33: FLORENCIA | F33: tres esquinas | G33: ALMUERZO
A34: 45889 | B34: 26000 | C34: ALMNUERZO | D34: AGOSTO | E34: FLORENCIA | F34: el porvenir | G34: ALMUERZO
A35: 45889 | B35: 44000 | C35: CENA DONDE FUENTE | D35: AGOSTO | E35: FLORENCIA | F35: el porvenir | G35: CENA
A36: 45893 | B36: 40000 | C36: DESAYUNO DONDE PIPE PARRILLA | D36: AGOSTO | E36: FLORENCIA | F36: el porvenir | G36: ALMUERZO
A37: 45893 | B37: 49000 | C37: ALMUERZO EN LAS GARZAS | D37: AGOSTO | E37: FLORENCIA | F37: el porvenir | G37: ALMUERZO
A38: 45894 | B38: 200000 | C38: ARREGLOS CASA EN ARRIENDO | D38: AGOSTO | E38: FLORENCIA | F38: el porvenir | G38: ARREGLOS
... A77: 46021 | B77: 266000 | C77: CENA FAMILIAR EN ALAMAR | D77: DICIEMBRE | E77: FLORENCIA | F77: URBANO | G77: CENA

Sheet 3-TOTAL GASTOS Y SSPP
A1: ITEM | B1: MONTO
A2: (+)ARRIENDO | B2: 700000
A3: (+)LUZ | B3: 151500 | E3: MES | F3: MONTO
A4: (+)AGUA | B4: 31559 | E4: MES ENERO | F4: =B14 -> 14057968
A5: (+)GAS | B5: 0 | E5: MES FEBRERO | F5: =B29 -> 3310580
A6: (+)INTERNET | B6: 80000 | E6: MES MARZO | F6: =B44 -> 3072536
A7: (+)PARABOLICA | B7: 43000 | E7: MES ABRIL | F7: =B59 -> 3455498
A8: (+)NETFLIX | B8: 26000 | E8: MES MAYO | F8: =B74 -> 3385952
A9: (+)ASEO MORRONGA | B9: 60000 | E9: MES JUNIO | F9: =B89 -> 3167049
A10: (+)MERCADO | B10: ='1-GASTOS MERCADO 2025'!I3 -> 1323709 | E10: MES JULIO | F10: =B104 -> 3337777
A11: (+)ALMUERZOS x 24 dias | B11: 642000 | E11: MES AGOSTO | F11: =B119 -> 4465156
A12: (+)CUOTA CARRO | B12: 0 | E12: MES SEPTIEMBRE | F12: =B134 -> 5206932
A13: (+)GASTOS POR OCIO | B13: ='2-GASTOS OCIO U OTROS'!B2 -> 11000200 | E13: MES OCTUBRE | F13: =B149 -> 6291127
A14: (=) TOTAL MES ENERO | B14: =SUM(B2:B13) -> 14057968 | E14: MES NOVIEMBRE | F14: =B164 -> 5725800
E15: MES DICIEMBRE | F15: =B178 -> 6068471
A16: ITEM | B16: MONTO
A17: (+)ARRIENDO | B17: 700000
A18: (+)LUZ | B18: 177590
A19: (+)AGUA | B19: 53329
A20: (+)GAS | B20: 19960
A21: (+)INTERNET | B21: 80000
A22: (+)PARABOLICA | B22: 43000
A23: (+)NETFLIX | B23: 26000
A24: (+)ASEO MORRONGA | B24: 260000
A25: (+)MERCADO | B25: ='1-GASTOS MERCADO 2025'!I4 -> 1174701
A26: (+)ALMUERZOS x 24 dias | B26: 642000
A27: (+)CUOTA CARRO | B27: 0
A28: (+)GASTOS POR OCIO | B28: ='2-GASTOS OCIO U OTROS'!K4 -> 134000
A29: (=) TOTAL MES FEBRERO | B29: =SUM(B17:B28) -> 3310580
A31: ITEM | B31: MONTO
A32: (+)ARRIENDO | B32: 700000
A33: (+)LUZ | B33: 195660
A34: (+)AGUA | B34: 57916
A35: (+)GAS | B35: 50680
A36: (+)INTERNET | B36: 80000
A37: (+)PARABOLICA | B37: 43000
A38: (+)NETFLIX | B38: 26000
A39: (+)ASEO MORRONGA | B39: 260000
A40: (+)MERCADO | B40: ='1-GASTOS MERCADO 2025'!I5 -> 1439280
A41: (+)ALMUERZOS x 24 dias | B41: 0
...

Sheet 4-RESULTADOS TOTALES
A1: MES | B1: INGRESOS | C1: EGRESOS | D1: VARIACIÓN PORCENTUAL | E1: ESTADO DE LA VARIACIÓN
A2: MES ENERO | B2: 14060000 | C2: ='3-TOTAL GASTOS Y SSPP'!B14 -> 14057968
A3: MES FEBRERO | B3: 3500000 | C3: ='3-TOTAL GASTOS Y SSPP'!B29 -> 3310580 | D3: =(C3-C2)/C3 -> -3.2463762 | E3: =IF(D3<0,"BAJÓ EL GASTO",IF(D3=0,"GASTO ESTABLE","SUBIÓ EL GASTO")) -> BAJÓ EL GASTO
A4: MES MARZO | B4: 3500000 | C4: ='3-TOTAL GASTOS Y SSPP'!B44 -> 3072536 | D4: =(C4-C3)/C4 -> -0.077474764 | E4: =IF(D4<0,"BAJÓ EL GASTO",IF(D4=0,"GASTO ESTABLE","SUBIÓ EL GASTO")) -> BAJÓ EL GASTO
A5: MES ABRIL | B5: 3500000 | C5: ='3-TOTAL GASTOS Y SSPP'!B59 -> 3455498 | D5: =(C5-C4)/C5 -> 0.11082686 | E5: =IF(D5<0,"BAJÓ EL GASTO",IF(D5=0,"GASTO ESTABLE","SUBIÓ EL GASTO")) -> SUBIÓ EL GASTO
A6: MES MAYO | B6: 3500000 | C6: ='3-TOTAL GASTOS Y SSPP'!B74 -> 3385952 | D6: =(C6-C5)/C6 -> -0.020539571 | E6: =IF(D6<0,"BAJÓ EL GASTO",IF(D6=0,"GASTO ESTABLE","SUBIÓ EL GASTO")) -> BAJÓ EL GASTO
A7: MES JUNIO | B7: 3500000 | C7: ='3-TOTAL GASTOS Y SSPP'!B89 -> 3167049 | D7: =(C7-C6)/C7 -> -0.069118918 | E7: =IF(D7<0,"BAJÓ EL GASTO",IF(D7=0,"GASTO ESTABLE","SUBIÓ EL GASTO")) -> BAJÓ EL GASTO
A8: MES JULIO | B8: 3700000 | C8: ='3-TOTAL GASTOS Y SSPP'!B104 -> 3337777 | D8: =(C8-C7)/C8 -> 0.051150212 | E8: =IF(D8<0,"BAJÓ EL GASTO",IF(D8=0,"GASTO ESTABLE","SUBIÓ EL GASTO")) -> SUBIÓ EL GASTO
A9: MES AGOSTO | B9: 4470000 | C9: ='3-TOTAL GASTOS Y SSPP'!B119 -> 4465156 | D9: =(C9-C8)/C9 -> 0.25248368 | E9: =IF(D9<0,"BAJÓ EL GASTO",IF(D9=0,"GASTO ESTABLE","SUBIÓ EL GASTO")) -> SUBIÓ EL GASTO
A10: MES SEPTIEMBRE | B10: 5220000 | C10: ='3-TOTAL GASTOS Y SSPP'!B134 -> 5206932 | D10: =(C10-C9)/C10 -> 0.14245932 | E10: =IF(D10<0,"BAJÓ EL GASTO",IF(D10=0,"GASTO ESTABLE","SUBIÓ EL GASTO")) -> SUBIÓ EL GASTO
A11: MES OCTUBRE | B11: 6200000 | C11: ='3-TOTAL GASTOS Y SSPP'!B149 -> 6291127 | D11: =(C11-C10)/C11 -> 0.17233717 | E11: =IF(D11<0,"BAJÓ EL GASTO",IF(D11=0,"GASTO ESTABLE","SUBIÓ EL GASTO")) -> SUBIÓ EL GASTO
A12: MES NOVIEMBRE | B12: 5730000 | C12: ='3-TOTAL GASTOS Y SSPP'!B164 -> 5725800 | D12: =(C12-C11)/C12 -> -0.098733277 | E12: =IF(D12<0,"BAJÓ EL GASTO",IF(D12=0,"GASTO ESTABLE","SUBIÓ EL GASTO")) -> BAJÓ EL GASTO
A13: MES DICIEMBRE | B13: 6070000 | C13: ='3-TOTAL GASTOS Y SSPP'!B178 -> 6068471 | D13: =(C13-C12)/C13 -> 0.056467436 | E13: =IF(D13<0,"BAJÓ EL GASTO",IF(D13=0,"GASTO ESTABLE","SUBIÓ EL GASTO")) -> SUBIÓ EL GASTO
A14: TOTALES | B14: =SUM(B2:B13) -> 62950000 | C14: =SUM(C2:C13) -> 61544846
